<?xml version="1.0" encoding="utf-8"?>
<!-- =================================================================================== -->
<!-- |    This document was autogenerated by xacro from mpl80.xacro                    | -->
<!-- |    EDITING THIS FILE BY HAND IS NOT RECOMMENDED                                 | -->
<!-- =================================================================================== -->
<robot name="motoman_mpl80">
  <!-- link list -->
  <link name="base_link">
    <visual>
      <origin rpy="0 0 0" xyz="0 0 0"/>
      <geometry>
        <mesh filename="./meshes/mpl80/visual/base_link.stl"/>
      </geometry>
      <material name="blue">
        <color rgba="0 0 1 1"/>
      </material>
    </visual>
    <collision>
      <origin rpy="0 0 0" xyz="0 0 0"/>
      <geometry>
        <mesh filename="./meshes/mpl80/collision/base_link.stl"/>
      </geometry>
      <material name="collision_material">
        <color rgba="1 0 0 1"/>
      </material>
    </collision>
  </link>
  <link name="link_s">
    <visual>
      <origin rpy="0 0 0" xyz="0 0 0"/>
      <geometry>
        <mesh filename="./meshes/mpl80/visual/link_s.stl"/>
      </geometry>
      <material name="blue"/>
    </visual>
    <collision>
      <origin rpy="0 0 0" xyz="0 0 0"/>
      <geometry>
        <mesh filename="./meshes/mpl80/collision/link_s.stl"/>
      </geometry>
      <material name="collision_material"/>
    </collision>
  </link>
  <link name="link_l">
    <visual>
      <origin rpy="0 0 0" xyz="0 0 0"/>
      <geometry>
        <mesh filename="./meshes/mpl80/visual/link_l.stl"/>
      </geometry>
      <material name="blue"/>
    </visual>
    <collision>
      <origin rpy="0 0 0" xyz="0 0 0"/>
      <geometry>
        <mesh filename="./meshes/mpl80/collision/link_l.stl"/>
      </geometry>
      <material name="collision_material"/>
    </collision>
  </link>
  <link name="link_u">
    <visual>
      <origin rpy="0 0 0" xyz="0 0 0"/>
      <geometry>
        <mesh filename="./meshes/mpl80/visual/link_u.stl"/>
      </geometry>
      <material name="blue"/>
    </visual>
    <collision>
      <origin rpy="0 0 0" xyz="0 0 0"/>
      <geometry>
        <mesh filename="./meshes/mpl80/collision/link_u.stl"/>
      </geometry>
      <material name="collision_material"/>
    </collision>
  </link>
  <link name="link_r">
    <visual>
      <origin rpy="0 0 0" xyz="0 0 0"/>
      <geometry>
        <mesh filename="./meshes/mpl80/visual/link_r.stl"/>
      </geometry>
      <material name="blue"/>
    </visual>
    <collision>
      <origin rpy="0 0 0" xyz="0 0 0"/>
      <geometry>
        <mesh filename="./meshes/mpl80/collision/link_r.stl"/>
      </geometry>
      <material name="collision_material"/>
    </collision>
  </link>
  <link name="link_b">
    <visual>
      <origin rpy="0 0 0" xyz="0 0 0"/>
      <geometry>
        <mesh filename="./meshes/mpl80/visual/link_b.stl"/>
      </geometry>
      <material name="blue"/>
    </visual>
    <collision>
      <origin rpy="0 0 0" xyz="0 0 0"/>
      <geometry>
        <mesh filename="./meshes/mpl80/collision/link_b.stl"/>
      </geometry>
      <material name="collision_material"/>
    </collision>
  </link>
  <link name="link_t">
    <visual>
      <origin rpy="0 0 0" xyz="0 0 0"/>
      <geometry>
        <mesh filename="./meshes/mpl80/visual/link_t.stl"/>
      </geometry>
      <material name="blue"/>
    </visual>
    <collision>
      <origin rpy="0 0 0" xyz="0 0 0"/>
      <geometry>
        <mesh filename="./meshes/mpl80/collision/link_t.stl"/>
      </geometry>
      <material name="collision_material"/>
    </collision>
  </link>
  <link name="tool0"/>
  <!-- end of link list -->
  <!-- joint list -->
  <joint name="joint_s" type="revolute">
    <origin rpy="0 0 0" xyz="0 0 0.540"/>
    <parent link="base_link"/>
    <child link="link_s"/>
    <axis xyz="0 0 1"/>
    <limit effort="100" lower="-3.14159" upper="3.14159" velocity="2.967"/>
  </joint>
  <joint name="joint_l" type="revolute">
    <origin rpy="0 0 0" xyz="0.145 0 0"/>
    <parent link="link_s"/>
    <child link="link_l"/>
    <axis xyz="0 1 0"/>
    <limit effort="100" lower="-1.5707" upper="2.3561" velocity="2.967"/>
  </joint>
  <joint name="joint_u" type="revolute">
    <origin rpy="0 0 0" xyz="0 0 0.870"/>
    <parent link="link_l"/>
    <child link="link_u"/>
    <axis xyz="0 -1 0"/>
    <limit effort="100" lower="-1.3962" upper="3.5953" velocity="2.967"/>
  </joint>
  <joint name="joint_r" type="fixed">
    <origin rpy="0 0 0" xyz="0 0 0.210"/>
    <parent link="link_u"/>
    <child link="link_r"/>
  </joint>
  <joint name="joint_b" type="revolute">
    <origin rpy="0 0 0" xyz="1.025 0 0"/>
    <parent link="link_r"/>
    <child link="link_b"/>
    <axis xyz="0 -1 0"/>
    <limit effort="100" lower="-0.6108" upper="3.0543" velocity="2.967"/>
  </joint>
  <joint name="joint_t" type="revolute">
    <origin rpy="0 0 0" xyz="0 0 -0.175"/>
    <parent link="link_b"/>
    <child link="link_t"/>
    <axis xyz="0 0 1"/>
    <limit effort="100" lower="-6.2831" upper="6.2831" velocity="6.108"/>
  </joint>
  <joint name="joint_t-tool0" type="fixed">
    <origin rpy="0 0 0" xyz="0 0 0"/>
    <parent link="link_t"/>
    <child link="tool0"/>
  </joint>
  <!-- end of joint list -->
  <!-- ROS base_link to Robot Manufacturer World Coordinates transform -->
  <link name="base"/>
  <joint name="base_link-base" type="fixed">
    <origin rpy="0 0 0" xyz="0 0 0.540"/>
    <parent link="base_link"/>
    <child link="base"/>
  </joint>
</robot>
