<?xml version="1.0" encoding="utf-8"?>
<!-- =================================================================================== -->
<!-- |    This document was autogenerated by xacro from bmda3.xacro                    | -->
<!-- |    EDITING THIS FILE BY HAND IS NOT RECOMMENDED                                 | -->
<!-- =================================================================================== -->
<robot name="motoman_bmda3">
  <!-- link list   -->
  <link name="base_link">
    <origin rpy="0 0 0" xyz="0 0 0"/>
  </link>
  <link name="base">
    <visual>
      <origin rpy="0 0 0" xyz="0 0 0"/>
      <geometry>
        <mesh filename="./meshes/bmda3/visual/base.stl"/>
      </geometry>
      <material name="">
        <color rgba="0.75294 0.75294 0.75294 1"/>
      </material>
    </visual>
    <collision>
      <origin rpy="0 0 0" xyz="0 0 0"/>
      <geometry>
        <mesh filename="./meshes/bmda3/collision/base.stl"/>
      </geometry>
    </collision>
  </link>
  <link name="torso_link_b1">
    <visual>
      <origin rpy="0 0 0" xyz="0 0 0"/>
      <geometry>
        <mesh filename="./meshes/bmda3/visual/torso_link.stl"/>
      </geometry>
      <material name="">
        <color rgba="0.75294 0.75294 0.75294 1"/>
      </material>
    </visual>
    <collision>
      <origin rpy="0 0 0" xyz="0 0 0"/>
      <geometry>
        <mesh filename="./meshes/bmda3/collision/torso_link.stl"/>
      </geometry>
    </collision>
  </link>
  <link name="right_link_l">
    <visual>
      <origin rpy="0 0 0" xyz="0 0 0"/>
      <geometry>
        <mesh filename="./meshes/bmda3/visual/right_link_l.stl"/>
      </geometry>
      <material name="">
        <color rgba="0.75294 0.75294 0.75294 1"/>
      </material>
    </visual>
    <collision>
      <origin rpy="0 0 0" xyz="0 0 0"/>
      <geometry>
        <mesh filename="./meshes/bmda3/collision/right_link_l.stl"/>
      </geometry>
    </collision>
  </link>
  <link name="right_link_e">
    <visual>
      <origin rpy="0 0 0" xyz="0 0 0"/>
      <geometry>
        <mesh filename="./meshes/bmda3/visual/right_link_e.stl"/>
      </geometry>
      <material name="">
        <color rgba="0.75294 0.75294 0.75294 1"/>
      </material>
    </visual>
    <collision>
      <origin rpy="0 0 0" xyz="0 0 0"/>
      <geometry>
        <mesh filename="./meshes/bmda3/collision/right_link_e.stl"/>
      </geometry>
    </collision>
  </link>
  <link name="right_link_u">
    <visual>
      <origin rpy="0 0 0" xyz="0 0 0"/>
      <geometry>
        <mesh filename="./meshes/bmda3/visual/right_link_u.stl"/>
      </geometry>
      <material name="">
        <color rgba="0.752941176470588 0.752941176470588 0.752941176470588 1"/>
      </material>
    </visual>
    <collision>
      <origin rpy="0 0 0" xyz="0 0 0"/>
      <geometry>
        <mesh filename="./meshes/bmda3/collision/right_link_u.stl"/>
      </geometry>
    </collision>
  </link>
  <link name="right_link_r">
    <visual>
      <origin rpy="0 0 0" xyz="0 0 0"/>
      <geometry>
        <mesh filename="./meshes/bmda3/visual/right_link_r.stl"/>
      </geometry>
      <material name="">
        <color rgba="0.752941176470588 0.752941176470588 0.752941176470588 1"/>
      </material>
    </visual>
    <collision>
      <origin rpy="0 0 0" xyz="0 0 0"/>
      <geometry>
        <mesh filename="./meshes/bmda3/collision/right_link_r.stl"/>
      </geometry>
    </collision>
  </link>
  <link name="right_link_b">
    <visual>
      <origin rpy="0 0 0" xyz="0 0 0"/>
      <geometry>
        <mesh filename="./meshes/bmda3/visual/right_link_b.stl"/>
      </geometry>
      <material name="">
        <color rgba="0.752941176470588 0.752941176470588 0.752941176470588 1"/>
      </material>
    </visual>
    <collision>
      <origin rpy="0 0 0" xyz="0 0 0"/>
      <geometry>
        <mesh filename="./meshes/bmda3/collision/right_link_b.stl"/>
      </geometry>
    </collision>
  </link>
  <link name="right_link_t">
    <visual>
      <origin rpy="0 0 0" xyz="0 0 0"/>
      <geometry>
        <mesh filename="./meshes/bmda3/visual/right_link_t.stl"/>
      </geometry>
      <material name="">
        <color rgba="0.752941176470588 0.752941176470588 0.752941176470588 1"/>
      </material>
    </visual>
    <collision>
      <origin rpy="0 0 0" xyz="0 0 0"/>
      <geometry>
        <mesh filename="./meshes/bmda3/collision/right_link_t.stl"/>
      </geometry>
    </collision>
  </link>
  <link name="right_tool0"/>
  <!-- Note that the redundant torso link b2 is introduced to match the phantom joint in the controller -->
  <link name="torso_link_b2">
    <visual>
      <origin rpy="0 0 0" xyz="0 0 0"/>
      <geometry>
        <mesh filename="./meshes/bmda3/visual/torso_link.stl"/>
      </geometry>
      <material name="">
        <color rgba="0.75294 0.75294 0.75294 1"/>
      </material>
    </visual>
    <collision>
      <origin rpy="0 0 0" xyz="0 0 0"/>
      <geometry>
        <mesh filename="./meshes/bmda3/collision/torso_link.stl"/>
      </geometry>
    </collision>
  </link>
  <link name="left_link_l">
    <visual>
      <origin rpy="0 0 0" xyz="0 0 0"/>
      <geometry>
        <mesh filename="./meshes/bmda3/visual/left_link_l.stl"/>
      </geometry>
      <material name="">
        <color rgba="0.752941176470588 0.752941176470588 0.752941176470588 1"/>
      </material>
    </visual>
    <collision>
      <origin rpy="0 0 0" xyz="0 0 0"/>
      <geometry>
        <mesh filename="./meshes/bmda3/collision/left_link_l.stl"/>
      </geometry>
    </collision>
  </link>
  <link name="left_link_e">
    <visual>
      <origin rpy="0 0 0" xyz="0 0 0"/>
      <geometry>
        <mesh filename="./meshes/bmda3/visual/left_link_e.stl"/>
      </geometry>
      <material name="">
        <color rgba="0.752941176470588 0.752941176470588 0.752941176470588 1"/>
      </material>
    </visual>
    <collision>
      <origin rpy="0 0 0" xyz="0 0 0"/>
      <geometry>
        <mesh filename="./meshes/bmda3/collision/left_link_e.stl"/>
      </geometry>
    </collision>
  </link>
  <link name="left_link_u">
    <visual>
      <origin rpy="0 0 0" xyz="0 0 0"/>
      <geometry>
        <mesh filename="./meshes/bmda3/visual/left_link_u.stl"/>
      </geometry>
      <material name="">
        <color rgba="0.752941176470588 0.752941176470588 0.752941176470588 1"/>
      </material>
    </visual>
    <collision>
      <origin rpy="0 0 0" xyz="0 0 0"/>
      <geometry>
        <mesh filename="./meshes/bmda3/collision/left_link_u.stl"/>
      </geometry>
    </collision>
  </link>
  <link name="left_link_r">
    <visual>
      <origin rpy="0 0 0" xyz="0 0 0"/>
      <geometry>
        <mesh filename="./meshes/bmda3/visual/left_link_r.stl"/>
      </geometry>
      <material name="">
        <color rgba="0.752941176470588 0.752941176470588 0.752941176470588 1"/>
      </material>
    </visual>
    <collision>
      <origin rpy="0 0 0" xyz="0 0 0"/>
      <geometry>
        <mesh filename="./meshes/bmda3/collision/left_link_r.stl"/>
      </geometry>
    </collision>
  </link>
  <link name="left_link_b">
    <visual>
      <origin rpy="0 0 0" xyz="0 0 0"/>
      <geometry>
        <mesh filename="./meshes/bmda3/visual/left_link_b.stl"/>
      </geometry>
      <material name="">
        <color rgba="0.752941176470588 0.752941176470588 0.752941176470588 1"/>
      </material>
    </visual>
    <collision>
      <origin rpy="0 0 0" xyz="0 0 0"/>
      <geometry>
        <mesh filename="./meshes/bmda3/collision/left_link_b.stl"/>
      </geometry>
    </collision>
  </link>
  <link name="left_link_t">
    <visual>
      <origin rpy="0 0 0" xyz="0 0 0"/>
      <geometry>
        <mesh filename="./meshes/bmda3/visual/left_link_t.stl"/>
      </geometry>
      <material name="">
        <color rgba="0.752941176470588 0.752941176470588 0.752941176470588 1"/>
      </material>
    </visual>
    <collision>
      <origin rpy="0 0 0" xyz="0 0 0"/>
      <geometry>
        <mesh filename="./meshes/bmda3/collision/left_link_t.stl"/>
      </geometry>
    </collision>
  </link>
  <link name="left_tool0"/>
  <!--end of link list -->
  <!-- joint list -->
  <joint name="base_link-base" type="fixed">
    <origin rpy="0 0 0" xyz="0 0 0"/>
    <parent link="base_link"/>
    <child link="base"/>
  </joint>
  <joint name="torso_joint_b1" type="revolute">
    <parent link="base"/>
    <child link="torso_link_b1"/>
    <origin rpy="0 0 0" xyz="0 0 0.3305"/>
    <axis xyz="0 0 1"/>
    <limit effort="0" lower="-3.1415" upper="3.1415" velocity="2.27"/>
  </joint>
  <joint name="right_joint_s" type="revolute">
    <parent link="torso_link_b1"/>
    <child link="right_link_l"/>
    <origin rpy="0 0 0" xyz="0.15002 -0.099 0.12951"/>
    <axis xyz="0 1 0"/>
    <limit effort="0" lower="-1.570" upper="3.1415" velocity="2.97"/>
  </joint>
  <joint name="right_joint_l" type="revolute">
    <parent link="right_link_l"/>
    <child link="right_link_e"/>
    <origin rpy="0 0 0" xyz="0 -0.151 0"/>
    <axis xyz="0 0 1"/>
    <limit effort="0" lower="-1.745" upper="1.745" velocity="2.62"/>
  </joint>
  <joint name="right_joint_e" type="revolute">
    <parent link="right_link_e"/>
    <child link="right_link_u"/>
    <origin rpy="0 0 0" xyz="0 -0.23549999999989 0"/>
    <axis xyz="0 1 0"/>
    <limit effort="0" lower="-2.966" upper="2.966" velocity="2.97"/>
  </joint>
  <joint name="right_joint_u" type="revolute">
    <parent link="right_link_u"/>
    <child link="right_link_r"/>
    <origin rpy="0 0 0" xyz="0.065002 -0.1445 0"/>
    <axis xyz="0 0 -1"/>
    <limit effort="0" lower="-1.396" upper="0.7504" velocity="2.97"/>
  </joint>
  <joint name="right_joint_r" type="revolute">
    <parent link="right_link_r"/>
    <child link="right_link_b"/>
    <origin rpy="0 0 0" xyz="0.35997 -0.05 0"/>
    <axis xyz="1 0 0"/>
    <limit effort="0" lower="-3.1415" upper="3.1415" velocity="3.49"/>
  </joint>
  <joint name="right_joint_b" type="revolute">
    <parent link="right_link_b"/>
    <child link="right_link_t"/>
    <origin rpy="0 0 0" xyz="0 0 0"/>
    <axis xyz="0 0 -1"/>
    <limit effort="0" lower="-1.9198" upper="1.9198" velocity="3.49"/>
  </joint>
  <joint name="right_joint_t" type="revolute">
    <parent link="right_link_t"/>
    <child link="right_tool0"/>
    <origin rpy="0 0 0" xyz="0.138 0 0"/>
    <axis xyz="1 0 0"/>
    <limit effort="0" lower="-4.712" upper="4.712" velocity="6.11"/>
  </joint>
  <!-- Note that the redundant torso joint b2 is introduced to match the phantom joint in the controller -->
  <joint name="torso_joint_b2" type="revolute">
    <parent link="base"/>
    <child link="torso_link_b2"/>
    <origin rpy="0 0 0" xyz="0 0 0.3305"/>
    <axis xyz="0 0 1"/>
    <limit effort="0" lower="-3.1415" upper="3.1415" velocity="2.27"/>
  </joint>
  <joint name="left_joint_s" type="revolute">
    <parent link="torso_link_b1"/>
    <child link="left_link_l"/>
    <origin rpy="0 0 0" xyz="0.15003 0.099 0.1295"/>
    <axis xyz="0 1 0"/>
    <limit effort="0" lower="-1.570" upper="3.1415" velocity="2.97"/>
  </joint>
  <joint name="left_joint_l" type="revolute">
    <parent link="left_link_l"/>
    <child link="left_link_e"/>
    <origin rpy="0 0 0" xyz="0 0.151 0"/>
    <axis xyz="0 0 -1"/>
    <limit effort="0" lower="-1.745" upper="1.745" velocity="2.62"/>
  </joint>
  <joint name="left_joint_e" type="revolute">
    <parent link="left_link_e"/>
    <child link="left_link_u"/>
    <origin rpy="0 0 0" xyz="0 0.23549999999989 0"/>
    <axis xyz="0 1 0"/>
    <limit effort="0" lower="-2.966" upper="2.966" velocity="2.97"/>
  </joint>
  <joint name="left_joint_u" type="revolute">
    <parent link="left_link_u"/>
    <child link="left_link_r"/>
    <origin rpy="0 0 0" xyz="0.065 0.1445 0"/>
    <axis xyz="0 0 1"/>
    <limit effort="0" lower="-1.396" upper="0.7504" velocity="2.97"/>
  </joint>
  <joint name="left_joint_r" type="revolute">
    <parent link="left_link_r"/>
    <child link="left_link_b"/>
    <origin rpy="0 0 0" xyz="0.35997 0.05 0"/>
    <axis xyz="-1 0 0"/>
    <limit effort="0" lower="-3.1415" upper="3.1415" velocity="3.49"/>
  </joint>
  <joint name="left_joint_b" type="revolute">
    <parent link="left_link_b"/>
    <child link="left_link_t"/>
    <origin rpy="0 0 0" xyz="0 0 0"/>
    <axis xyz="0 0 1"/>
    <limit effort="0" lower="-1.9198" upper="1.9198" velocity="3.49"/>
  </joint>
  <joint name="left_joint_t" type="revolute">
    <parent link="left_link_t"/>
    <child link="left_tool0"/>
    <origin rpy="0 0 0" xyz="0.138 0 0"/>
    <axis xyz="-1 0 0"/>
    <limit effort="0" lower="-4.712" upper="4.712" velocity="6.11"/>
  </joint>
  <!-- end of joint list -->
</robot>
