<?xml version="1.0" encoding="utf-8"?>
<!-- =================================================================================== -->
<!-- |    This document was autogenerated by xacro from epx1250.xacro                  | -->
<!-- |    EDITING THIS FILE BY HAND IS NOT RECOMMENDED                                 | -->
<!-- =================================================================================== -->
<robot name="motoman_epx1250">
  <!-- link list -->
  <link name="base_link">
    <visual>
      <origin rpy="0 0 0" xyz="0 0 0"/>
      <geometry>
        <mesh filename="./meshes/epx1250/visual/base_link.stl"/>
      </geometry>
      <material name="blue">
        <color rgba="0 0 1 1"/>
      </material>
    </visual>
    <collision>
      <geometry>
        <mesh filename="./meshes/epx1250/collision/base_link.stl"/>
      </geometry>
      <material name="yellow">
        <color rgba="0 1 1 1"/>
      </material>
    </collision>
  </link>
  <link name="link_s">
    <visual>
      <origin rpy="0 0 0" xyz="0 0 0"/>
      <geometry>
        <mesh filename="./meshes/epx1250/visual/link_s.stl"/>
      </geometry>
      <material name="blue"/>
    </visual>
    <collision>
      <origin rpy="0 0 0" xyz="0 0 0"/>
      <geometry>
        <mesh filename="./meshes/epx1250/collision/link_s.stl"/>
      </geometry>
      <material name="yellow"/>
    </collision>
  </link>
  <link name="link_l">
    <visual>
      <origin rpy="0 0 0" xyz="0 0 0"/>
      <geometry>
        <mesh filename="./meshes/epx1250/visual/link_l.stl"/>
      </geometry>
      <material name="blue"/>
    </visual>
    <collision>
      <origin rpy="0 0 0" xyz="0 0 0"/>
      <geometry>
        <mesh filename="./meshes/epx1250/collision/link_l.stl"/>
      </geometry>
      <material name="yellow"/>
    </collision>
  </link>
  <link name="link_u">
    <visual>
      <origin rpy="0 0 0" xyz="0 0 0"/>
      <geometry>
        <mesh filename="./meshes/epx1250/visual/link_u.stl"/>
      </geometry>
      <material name="blue"/>
    </visual>
    <collision>
      <origin rpy="0 0 0" xyz="0 0 0"/>
      <geometry>
        <mesh filename="./meshes/epx1250/collision/link_u.stl"/>
      </geometry>
      <material name="yellow"/>
    </collision>
  </link>
  <link name="link_r">
    <visual>
      <origin rpy="0 0 0" xyz="0.520 0 0"/>
      <geometry>
        <mesh filename="./meshes/epx1250/visual/link_r.stl"/>
      </geometry>
      <material name="blue"/>
    </visual>
    <collision>
      <origin rpy="0 0 0" xyz="0.520 0 0"/>
      <geometry>
        <mesh filename="./meshes/epx1250/collision/link_r.stl"/>
      </geometry>
      <material name="yellow"/>
    </collision>
  </link>
  <link name="link_b">
    <visual>
      <origin rpy="0 0 0" xyz="0 0 0"/>
      <geometry>
        <mesh filename="./meshes/epx1250/visual/link_b.stl"/>
      </geometry>
      <material name="blue"/>
    </visual>
    <collision>
      <origin rpy="0 0 0" xyz="0 0 0"/>
      <geometry>
        <mesh filename="./meshes/epx1250/collision/link_b.stl"/>
      </geometry>
      <material name="yellow"/>
    </collision>
  </link>
  <link name="link_t">
    <visual>
      <origin rpy="0 0 0" xyz="0 0 0"/>
      <geometry>
        <mesh filename="./meshes/epx1250/visual/link_t.stl"/>
      </geometry>
      <material name="black">
        <color rgba="1 1 1 1"/>
      </material>
    </visual>
    <collision>
      <origin rpy="0 0 0" xyz="0 0 0"/>
      <geometry>
        <mesh filename="./meshes/epx1250/collision/link_t.stl"/>
      </geometry>
      <material name="black"/>
    </collision>
  </link>
  <link name="tool0"/>
  <!-- end of link list -->
  <!-- joint list -->
  <joint name="joint_s" type="revolute">
    <origin rpy="0 0 0" xyz="0 0 0.310"/>
    <parent link="base_link"/>
    <child link="link_s"/>
    <axis xyz="0 0 1"/>
    <limit effort="0" lower="-2.96705972839" upper="2.96705972839" velocity="3.22885911619"/>
  </joint>
  <joint name="joint_l" type="revolute">
    <origin rpy="0 0 0" xyz="0.200 0 0"/>
    <parent link="link_s"/>
    <child link="link_l"/>
    <axis xyz="0 1 0"/>
    <limit effort="0" lower="-1.1344640138" upper="2.09439510239" velocity="3.22885911619"/>
  </joint>
  <joint name="joint_u" type="revolute">
    <origin rpy="0 0 0" xyz="0 0 0.520"/>
    <parent link="link_l"/>
    <child link="link_u"/>
    <axis xyz="0 1 0"/>
    <limit effort="0" lower="-2.87979326579" upper="3.57792496659" velocity="3.22885911619"/>
  </joint>
  <joint name="joint_r" type="revolute">
    <origin rpy="0 0 0" xyz="0 0 0.130"/>
    <parent link="link_u"/>
    <child link="link_r"/>
    <axis xyz="1 0 0"/>
    <limit effort="0" lower="-3.31612557879" upper="3.31612557879" velocity="6.28318530718"/>
  </joint>
  <joint name="joint_b" type="revolute">
    <origin rpy="0 0 0" xyz="0.520 0 0"/>
    <parent link="link_r"/>
    <child link="link_b"/>
    <axis xyz="0 1 0"/>
    <limit effort="0" lower="-2.53072741539" upper="2.53072741539" velocity="7.15584993318"/>
  </joint>
  <joint name="joint_t" type="revolute">
    <origin rpy="0 0 0" xyz="0.0865 0 0"/>
    <parent link="link_b"/>
    <child link="link_t"/>
    <axis xyz="1 0 0"/>
    <limit effort="0" lower="-6.28318530718" upper="6.28318530718" velocity="8.72664625997"/>
  </joint>
  <joint name="joint_t-tool0" type="fixed">
    <origin rpy="0 1.57079632679 0" xyz="0 0 0"/>
    <parent link="link_t"/>
    <child link="tool0"/>
  </joint>
  <!-- end of joint list -->
  <!-- ROS base_link to Robot Manufacturer World Coordinates transform -->
  <link name="base"/>
  <joint name="base_link-base" type="fixed">
    <origin rpy="0 0 0" xyz="0 0 0.310"/>
    <parent link="base_link"/>
    <child link="base"/>
  </joint>
</robot>
